Traceback (most recent call last):
  File "/Users/stefanofuri/Uni/uni-internship/kt_env/lib/python3.10/site-packages/jupyter_cache/executors/utils.py", line 58, in single_nb_execution
    executenb(
  File "/Users/stefanofuri/Uni/uni-internship/kt_env/lib/python3.10/site-packages/nbclient/client.py", line 1204, in execute
    return NotebookClient(nb=nb, resources=resources, km=km, **kwargs).execute()
  File "/Users/stefanofuri/Uni/uni-internship/kt_env/lib/python3.10/site-packages/nbclient/util.py", line 84, in wrapped
    return just_run(coro(*args, **kwargs))
  File "/Users/stefanofuri/Uni/uni-internship/kt_env/lib/python3.10/site-packages/nbclient/util.py", line 62, in just_run
    return loop.run_until_complete(coro)
  File "/opt/homebrew/Cellar/python@3.10/3.10.9/Frameworks/Python.framework/Versions/3.10/lib/python3.10/asyncio/base_events.py", line 649, in run_until_complete
    return future.result()
  File "/Users/stefanofuri/Uni/uni-internship/kt_env/lib/python3.10/site-packages/nbclient/client.py", line 663, in async_execute
    await self.async_execute_cell(
  File "/Users/stefanofuri/Uni/uni-internship/kt_env/lib/python3.10/site-packages/nbclient/client.py", line 965, in async_execute_cell
    await self._check_raise_for_error(cell, cell_index, exec_reply)
  File "/Users/stefanofuri/Uni/uni-internship/kt_env/lib/python3.10/site-packages/nbclient/client.py", line 862, in _check_raise_for_error
    raise CellExecutionError.from_cell_and_msg(cell, exec_reply_content)
nbclient.exceptions.CellExecutionError: An error occurred while executing the following cell:
------------------
q%use multik
------------------

org.jetbrains.kotlinx.jupyter.repl.impl.JupyterCompilerImpl.compileSync(JupyterCompilerImpl.kt:174)
org.jetbrains.kotlinx.jupyter.repl.impl.InternalEvaluatorImpl.eval(InternalEvaluatorImpl.kt:99)
org.jetbrains.kotlinx.jupyter.repl.impl.CellExecutorImpl$execute$1$result$1.invoke(CellExecutorImpl.kt:75)
org.jetbrains.kotlinx.jupyter.repl.impl.CellExecutorImpl$execute$1$result$1.invoke(CellExecutorImpl.kt:73)
org.jetbrains.kotlinx.jupyter.ReplForJupyterImpl.withHost(repl.kt:665)
org.jetbrains.kotlinx.jupyter.repl.impl.CellExecutorImpl.execute(CellExecutorImpl.kt:73)
org.jetbrains.kotlinx.jupyter.repl.CellExecutor$DefaultImpls.execute$default(CellExecutor.kt:15)
org.jetbrains.kotlinx.jupyter.ReplForJupyterImpl$evalEx$1.invoke(repl.kt:478)
org.jetbrains.kotlinx.jupyter.ReplForJupyterImpl$evalEx$1.invoke(repl.kt:469)
org.jetbrains.kotlinx.jupyter.ReplForJupyterImpl.withEvalContext(repl.kt:432)
org.jetbrains.kotlinx.jupyter.ReplForJupyterImpl.evalEx(repl.kt:469)
org.jetbrains.kotlinx.jupyter.messaging.ProtocolKt$shellMessagesHandler$2$res$1.invoke(protocol.kt:318)
org.jetbrains.kotlinx.jupyter.messaging.ProtocolKt$shellMessagesHandler$2$res$1.invoke(protocol.kt:312)
org.jetbrains.kotlinx.jupyter.JupyterExecutorImpl$runExecution$execThread$1.invoke(execution.kt:37)
org.jetbrains.kotlinx.jupyter.JupyterExecutorImpl$runExecution$execThread$1.invoke(execution.kt:32)
kotlin.concurrent.ThreadsKt$thread$thread$1.run(Thread.kt:30)
org.jetbrains.kotlinx.jupyter.exceptions.ReplCompilerException: Line_0.jupyter.kts (1:13 - 13) Expecting an element

